Workbook

Sheet Especialistas
A1: Salario
A2: 4312000 | C2: Cantidad de datos | D2: =+COUNT(A2:A81) -> 80 | E2: >=CONTAR(A2:A81)
A3: 4250000 | C3: Cantidad de intervalos | D3: =SQRT(D2) -> 8.9442719 | E3: >=RAIZ(D2)
A4: 3197319 | C4: Cantidad de intervalos | D4: =INT(D3) -> 8 | E4: >=ENTERO(D3)
A5: 3080000
A6: 1000000 | C6: Valor máximo | D6: =MAX(A2:A81) -> 7500000 | E6: >=MAX(A2:A81)
A7: 2300000 | C7: Valor mínimo | D7: =MIN(A2:A81) -> 900000 | E7: >=MIN(A2:A81)
A8: 4066000
A9: 6085454 | C9: Amplitud intervalo | D9: =(D6-D7)/D4 -> 825000 | E9: >=(D6-D7)/D4
A10: 6085454
A11: 6085454 | C11: Clase | D11: Frecuencia | E11: % acumulado
A12: 6085454 | C12: 900000 | D12: 1 | E12: 0.0125
A13: 6085454 | C13: 1725000 | D13: 4 | E13: 0.0625
A14: 6085454 | C14: 2550000 | D14: 2 | E14: 0.0875
A15: 6085454 | C15: 3375000 | D15: 12 | E15: 0.2375
A16: 6085454 | C16: 4200000 | D16: 7 | E16: 0.325
A17: 6085454 | C17: 5025000 | D17: 12 | E17: 0.475
A18: 3729631 | C18: 5850000 | D18: 20 | E18: 0.725
A19: 1000000 | C19: 6675000 | D19: 19 | E19: 0.9625
A20: 3500000 | C20: y mayor... | D20: 3 | E20: 1
A21: 2800000
A22: 3000000 | C22: Frecuencia de $6.300.000 | D22: =+COUNTIF(A2:A81,"=6300000") -> 5 | E22: >=CONTAR.SI(A2:A81;"=6300000")
A23: 3000000 | C23: P(x = 6.300.000) | D23: =+D22/D2 -> 0.0625 | E23: >=D22/D2
A24: 3696000 | C24: Frecuencia de <$6.300.000 | D24: =+COUNTIF(A2:A81,"<=6300000") -> 75 | E24: >=CONTAR.SI(A2:A81;"<=6300000")
A25: 4312000 | C25: P(x <= 6.300.000) | D25: =+D24/D2 -> 0.9375 | E25: >=D24/D2
A26: 4928000
A27: 3351720 | C27: Frecuencia de $4.000.000 | D27: =+COUNTIF(A2:A81,"=4000000") -> 2
A28: 5000000 | C28: P(x = 4.000.000) | D28: =+D27/D2 -> 0.025 | E28: Probabilidad individual
A29: 7000000 | C29: Frecuencia de <$4.000.000 | D29: =+COUNTIF(A2:A81,"<=4000000") -> 25
A30: 5500000 | C30: P(x <= 4.000.000) | D30: =+D29/D2 -> 0.3125 | E30: Probabilidad acumulada
A31: 5500000
A32: 4000000 | C32: Promedio | D32: =AVERAGE(A2:A81) -> 4731496.3 | E32: >=PROMEDIO(A2:A81)
A33: 2700000 | C33: Mediana | D33: =MEDIAN(A2:A81) -> 5500000 | E33: >=MEDIANA(A2:A81)
A34: 2396000 | C34: Moda | D34: =MODE(A2:A81) -> 6085454 | E34: >=MODA(A2:A81)
A35: 1378910
A36: 4224000 | C36: PERCENTILES | D36: SALARIO
A37: 3000000 | C37: 0.01 | D37: =PERCENTILE($A$2:$A$81,C37) -> 922120 | E37: >=PERCENTIL($A$2:$A$81;C27)
A38: 5934172 | C38: 0.1 | D38: =PERCENTILE($A$2:$A$81,C38) -> 2790000
A39: 4000000 | C39: 0.2 | D39: =PERCENTILE($A$2:$A$81,C39) -> 3080000
A40: 5531839 | C40: 0.25 | D40: =PERCENTILE($A$2:$A$81,C40) -> 3635518.2
...

Sheet Profesionales
A1: Salario
A2: 2500000 | C2: Cantidad de datos | D2: =+COUNT(A2:A1134) -> 1133
A3: 2000000 | C3: Cantidad de intervalos | D3: =SQRT(D2) -> 33.660065
A4: 2695000 | C4: Cantidad de intervalos | D4: =INT(D3) -> 33
A5: 1500000
A6: 3000000 | C6: Valor máximo | D6: =MAX(A2:A1134) -> 12000000
A7: 1000000 | C7: Valor mínimo | D7: =MIN(A2:A1134) -> 500000
A8: 1700000
A9: 1289700 | C9: Amplitud intervalo | D9: =(D6-D7)/D4 -> 348484.85
A10: 1379000
A11: 2464000 | C11: Clase | D11: Frecuencia | E11: % acumulado
A12: 2000000 | C12: 500000 | D12: 1 | E12: 0.00088339223
A13: 3672000 | C13: 848484.85 | D13: 25 | E13: 0.022968198
A14: 3300000 | C14: 1196969.7 | D14: 57 | E14: 0.073321555
A15: 1000000 | C15: 1545454.5 | D15: 127 | E15: 0.18551237
A16: 3500000 | C16: 1893939.4 | D16: 138 | E16: 0.30742049
A17: 900000 | C17: 2242424.2 | D17: 149 | E17: 0.43904594
A18: 4312000 | C18: 2590909.1 | D18: 116 | E18: 0.54151943
A19: 4000000 | C19: 2939393.9 | D19: 56 | E19: 0.5909894
A20: 2200000 | C20: 3287878.8 | D20: 100 | E20: 0.67932862
A21: 2500000 | C21: 3636363.6 | D21: 55 | E21: 0.72791519
A22: 5000000 | C22: 3984848.5 | D22: 34 | E22: 0.75795053
A23: 2464000 | C23: 4333333.3 | D23: 93 | E23: 0.84010601
... A44: 1600000 | C44: 11651515 | D44: 0 | E44: 0.99911661
A45: 1500000 | C45: y mayor... | D45: 1 | E45: 1
A46: 1500000
A47: 2464000 | C47: Frecuencia de $3.000.000 | D47: =+COUNTIF(A2:A1134,"=3000000") -> 66
A48: 2464000 | C48: P(x = 3.000.000) | D48: =+D47/D2 -> 0.058252427
A49: 3500000 | C49: Frecuencia de <$3.000.000 | D49: =+COUNTIF(A2:A1134,"<=3000000") -> 741
A50: 1500000 | C50: P(x <= 3.000.000) | D50: =+D49/D2 -> 0.65401589
A51: 2000000
A52: 3000000 | C52: Frecuencia de $2.000.000 | D52: =+COUNTIF(A2:A1134,"=2000000") -> 90
A53: 2500000 | C53: P(x = 2.000.000) | D53: =+D52/D2 -> 0.079435128 | E53: Probabilidad individual
A54: 1500000 | C54: Frecuencia de <$2.000.000 | D54: =+COUNTIF(A2:A1134,"<=2000000") -> 464
A55: 1567000 | C55: P(x <= 2.000.000) | D55: =+D54/D2 -> 0.40953222 | E55: Probabilidad acumulada
A56: 1050000
A57: 4574257
A58: 2200000 | C58: Promedio | D58: =AVERAGE(A2:A1134) -> 2808479.8
A59: 2800000 | C59: Mediana | D59: =MEDIAN(A2:A1134) -> 2500000
A60: 2100000 | C60: Moda | D60: =MODE(A2:A1134) -> 2000000
...

Sheet Distribuciones de probabilidad
A1: Distribución Normal:
A2: Parámetros:
A3: Media | B3: µ | C3: =+AVERAGE(Especialistas!A2:A81) -> 4731496.3 | D3: >=PROMEDIO(Especialistas!A2:A81)
A4: Desviación estándar | B4: σ | C4: =+STDEV(Especialistas!A2:A81) -> 1573953.3 | D4: >=DESVEST(Especialistas!A2:A81)
B6: x | C6: Prob.
A7: P(x = 4.000.000) | B7: 4000000 | C7: =+NORMDIST(B7,C3,C4,0) -> 2.2751805e-07 | D7: Prob. Indiv. | E7: f(x) | F7: >=DISTR.NORM(B7;C3;C4;0)
A8: P(x < 4.000.000) | B8: 4000000 | C8: =+NORMDIST(B8,C3,C4,1) -> 0.32105491 | D8: Prob. Acum. | E8: F(x) | F8: >=DISTR.NORM(B8;C3;C4;1)
A9: P(x = 4.731.496) | B9: =+C3 -> 4731496.3 | C9: =+NORMDIST(B9,C3,C4,0) -> 2.5346514e-07 | D9: Prob. Indiv. | E9: f(x)
A10: P(x < 4.731.496) | B10: =+C3 -> 4731496.3 | C10: =+NORMDIST(B10,C3,C4,1) -> 0.5 | D10: Prob. Acum. | E10: F(x)
A11: P(x = 1.000.000) | B11: 1000000 | C11: =+NORMDIST(B11,C3,C4,0) -> 1.5255321e-08
A12: P(x < 1.000.000) | B12: 1000000 | C12: =+NORMDIST(B12,C3,C4,1) -> 0.0088753065
A13: P(x = 500.000) | B13: 500000 | C13: =+NORMDIST(B13,C3,C4,0) -> 6.8301172e-09
A14: P(x < 500.000) | B14: 500000 | C14: =+NORMDIST(B14,C3,C4,1) -> 0.0035892182
A15: P(x = -100.000) | B15: -100000 | C15: =+NORMDIST(B15,C3,C4,0) -> 2.2792125e-09
A16: P(x < -100.000) | B16: -100000 | C16: =+NORMDIST(B16,C3,C4,1) -> 0.0010715246
A18: P(<x) | B18: x
A19: 1e-06 | B19: =+NORMINV(A19,C3,C4) -> -2750171.4 | C19: >=DISTR.NORM.INV(A19;C3;C4)
A20: 0.1 | B20: =+NORMINV(A20,C3,C4) -> 2714394
A21: 0.32 | B21: =+NORMINV(A21,C3,C4) -> 3995360.2
A22: 0.4 | B22: =+NORMINV(A22,C3,C4) -> 4332739.8
A23: 0.5 | B23: =+NORMINV(A23,C3,C4) -> 4731496.3
A24: 0.7 | B24: =+NORMINV(A24,C3,C4) -> 5556878.2
A25: 0.99999 | B25: =+NORMINV(A25,C3,C4) -> 11444235
A28: Distribución Normal Estándar:
B29: x | C29: z | D29: Prob.
A30: P(x < 4.000.000) | B30: 4000000 | C30: =+(B30-C3)/C4 -> -0.46475095 | D30: =+_xlfn.NORM.S.DIST(C30,1) -> 0.32105491 | E30: Prob. Acum. | F30: F(x) | G30: >=DISTR.NORM.ESTAND.N(C30;1)
A32: P(<x) | B32: z | C32: x
A33: 1e-06 | B33: =+_xlfn.NORM.S.INV(A33) -> -4.7534243 | C33: =B33*C4+C3 -> -2750171.4
A34: 0.1 | B34: =+_xlfn.NORM.S.INV(A34) -> -1.2815516 | C34: =B34*$C$4+$C$3 -> 2714394
A35: 0.32 | B35: =+_xlfn.NORM.S.INV(A35) -> -0.4676988 | C35: =B35*$C$4+$C$3 -> 3995360.2
A36: 0.4 | B36: =+_xlfn.NORM.S.INV(A36) -> -0.2533471 | C36: =B36*$C$4+$C$3 -> 4332739.8
A37: 0.5 | B37: =+_xlfn.NORM.S.INV(A37) -> 0 | C37: =B37*$C$4+$C$3 -> 4731496.3
A38: 0.7 | B38: =+_xlfn.NORM.S.INV(A38) -> 0.52440051 | C38: =B38*$C$4+$C$3 -> 5556878.2
A39: 0.99999 | B39: =+_xlfn.NORM.S.INV(A39) -> 4.2648908 | C39: =B39*$C$4+$C$3 -> 11444235
A42: Distribución triangular:
A43: Parámetros:
A44: Mínimo | B44: a | C44: =+MIN(Especialistas!A2:A81) -> 900000 | D44: >=MIN(Especialistas!A2:A81)
A45: Más probable | B45: b | C45: =+MODE(Especialistas!A2:A81) -> 6085454 | D45: >=MODA(Especialistas!A2:A81)
A46: Máximo | B46: c | C46: =+MAX(Especialistas!A2:A81) -> 7500000 | D46: >=MAX(Especialistas!A2:A81)
B48: x | C48: Prob.
...
